Workbook

Sheet JSON
A1: endpoint | B1: imsi | C1: QC packCode | D1: packCode | E1: quota | F1: subscriptionId | G1: packOrderSn
A2: qrypacklist | B2: 454120335190110-454120335190112 | D2: =IF(C2<>"",INDEX(PackList!B:B,MATCH(C2,PackList!E:E,0)),"")
D3: =IF(C3<>"",INDEX(PackList!B:B,MATCH(C3,PackList!E:E,0)),"")
D4: =IF(C4<>"",INDEX(PackList!B:B,MATCH(C4,PackList!E:E,0)),"")
D5: =IF(C5<>"",INDEX(PackList!B:B,MATCH(C5,PackList!E:E,0)),"")
D6: =IF(C6<>"",INDEX(PackList!B:B,MATCH(C6,PackList!E:E,0)),"")
D7: =IF(C7<>"",INDEX(PackList!B:B,MATCH(C7,PackList!E:E,0)),"")
D8: =IF(C8<>"",INDEX(PackList!B:B,MATCH(C8,PackList!E:E,0)),"")
D9: =IF(C9<>"",INDEX(PackList!B:B,MATCH(C9,PackList!E:E,0)),"")
D10: =IF(C10<>"",INDEX(PackList!B:B,MATCH(C10,PackList!E:E,0)),"")
D11: =IF(C11<>"",INDEX(PackList!B:B,MATCH(C11,PackList!E:E,0)),"")
D12: =IF(C12<>"",INDEX(PackList!B:B,MATCH(C12,PackList!E:E,0)),"")
D13: =IF(C13<>"",INDEX(PackList!B:B,MATCH(C13,PackList!E:E,0)),"")
D14: =IF(C14<>"",INDEX(PackList!B:B,MATCH(C14,PackList!E:E,0)),"")
... D98: =IF(C98<>"",INDEX(PackList!B:B,MATCH(C98,PackList!E:E,0)),"")

Sheet PackList
A1: Vendor | B1: Package ID | C1: Vendor Package ID | D1: Package Type | E1: Package Name | F1: Catalog | G1: Status | H1: Update Time | I1: Tags
A2: CMLink-00 | B2: 117748 | C2: D2510091019022885159 | D2: Additional Package | E2: MA002178 | F2: Quadcell | G2: Active | H2: 10/09/2025 10:19:02 | I2: 6451M / 0Kbps / Natural Day
A3: CMLink-00 | B3: 117747 | C3: D2510091013080399367 | D3: Additional Package | E3: MA002181 | F3: Quadcell | G3: Active | H3: 10/09/2025 10:13:08 | I3: 33792M / 0Kbps / Natural Day
A4: CMLink-00 | B4: 117745 | C4: D2510091013069999576 | D4: Additional Package | E4: MA002179 | F4: Quadcell | G4: Active | H4: 10/09/2025 10:13:07 | I4: 11059M / 0Kbps / Natural Day
A5: CMLink-00 | B5: 117746 | C5: D2510091013075206435 | D5: Additional Package | E5: MA002180 | F5: Quadcell | G5: Active | H5: 10/09/2025 10:13:07 | I5: 21504M / 0Kbps / Natural Day
A6: CMLink-00 | B6: 117743 | C6: D2510091013058746839 | D6: Additional Package | E6: MA002176 | F6: Quadcell | G6: Active | H6: 10/09/2025 10:13:06 | I6: 1024M / 0Kbps / Natural Day
A7: CMLink-00 | B7: 117744 | C7: D2510091013064050690 | D7: Additional Package | E7: MA002177 | F7: Quadcell | G7: Active | H7: 10/09/2025 10:13:06 | I7: 3072M / 0Kbps / Natural Day
A8: CMLink-00 | B8: 117742 | C8: D2510091013053778436 | D8: Additional Package | E8: MA002175 | F8: Quadcell | G8: Active | H8: 10/09/2025 10:13:05 | I8: 33792M / 0Kbps / Natural Day
A9: CMLink-00 | B9: 117740 | C9: D2510091013043074163 | D9: Additional Package | E9: MA002173 | F9: Quadcell | G9: Active | H9: 10/09/2025 10:13:04 | I9: 11059M / 0Kbps / Natural Day
A10: CMLink-00 | B10: 117741 | C10: D2510091013048035939 | D10: Additional Package | E10: MA002174 | F10: Quadcell | G10: Active | H10: 10/09/2025 10:13:04 | I10: 21504M / 0Kbps / Natural Day
A11: CMLink-00 | B11: 117738 | C11: D2510091013030166142 | D11: Additional Package | E11: MA002171 | F11: Quadcell | G11: Active | H11: 10/09/2025 10:13:03 | I11: 3072M / 0Kbps / Natural Day
A12: CMLink-00 | B12: 117739 | C12: D2510091013036387266 | D12: Additional Package | E12: MA002172 | F12: Quadcell | G12: Active | H12: 10/09/2025 10:13:03 | I12: 6451M / 0Kbps / Natural Day
... A118: CMHK | B118: 117086 | C118: 300266 | D118: Additional Package | E118: TestCMHKProfile | F118: Quadcell | G118: Active | H118: 09/16/2025 12:38:36 | I118: 1024M / 0Kbps / Natural Day
A119: CMHK | B119: 117081 | D119: Basic Plan | E119: Quadcell_Basic_Plan | F119: QUADCELL COMMUNICATIONS LIMITED | G119: Active | H119: 09/15/2025 17:32:17 | I119: -
A120: CMLink-00 | B120: 117063 | C120: D2509151017024426053 | D120: Additional Package | E120: MA002075 | F120: Quadcell | G120: Active | H120: 09/15/2025 10:17:02 | I120: 20480M / 0Kbps / 24 Hours
A121: CMLink-00 | B121: 117050 | C121: D2509121509025901969 | D121: Additional Package | E121: MA002074 | F121: Quadcell | G121: Active | H121: 09/12/2025 15:09:02 | I121: 20480M / 128Kbps / Natural Day
A122: CMLink-01 | B122: 116928 | C122: D2509101056022870723 | D122: Additional Package | E122: TESTMNT002 | F122: Quadcell | G122: Active | H122: 09/10/2025 10:56:02 | I122: 51200M / 20Mbps / Natural Day
A123: CMLink-01 | B123: 116927 | C123: D2509101055208967810 | D123: Additional Package | E123: TESTMNT002 | F123: Quadcell | G123: Active | H123: 09/10/2025 10:55:20 | I123: 51200M / 20Mbps / Natural Day
A124: CMLink-00 | B124: 116790 | C124: D2509051538073471271 | D124: Additional Package | E124: MA002073 | F124: Quadcell | G124: Active | H124: 09/05/2025 15:38:07 | I124: 100G / 0Kbps / 24 Hours
A125: CMLink-00 | B125: 116788 | C125: D2509051538062676688 | D125: Additional Package | E125: MA002071 | F125: Quadcell | G125: Active | H125: 09/05/2025 15:38:06 | I125: 30G / 0Kbps / 24 Hours
A126: CMLink-00 | B126: 116789 | C126: D2509051538068436610 | D126: Additional Package | E126: MA002072 | F126: Quadcell | G126: Active | H126: 09/05/2025 15:38:06 | I126: 50G / 0Kbps / 24 Hours
A127: CMLink-00 | B127: 116786 | C127: D2509051538051925409 | D127: Additional Package | E127: MA002069 | F127: Quadcell | G127: Active | H127: 09/05/2025 15:38:05 | I127: 10G / 0Kbps / 24 Hours
A128: CMLink-00 | B128: 116787 | C128: D2509051538057192868 | D128: Additional Package | E128: MA002070 | F128: Quadcell | G128: Active | H128: 09/05/2025 15:38:05 | I128: 20G / 0Kbps / 24 Hours
A129: CMLink-00 | B129: 116784 | C129: D2509051538041799705 | D129: Additional Package | E129: MA002067 | F129: Quadcell | G129: Active | H129: 09/05/2025 15:38:04 | I129: 50G / 0Kbps / 24 Hours
A130: CMLink-00 | B130: 116785 | C130: D2509051538046833654 | D130: Additional Package | E130: MA002068 | F130: Quadcell | G130: Active | H130: 09/05/2025 15:38:04 | I130: 100G / 0Kbps / 24 Hours
A131: CMLink-00 | B131: 116782 | C131: D2509051538031056434 | D131: Additional Package | E131: MA002065 | F131: Quadcell | G131: Active | H131: 09/05/2025 15:38:03 | I131: 20G / 0Kbps / 24 Hours
... A602: CMLink-00 | B602: 116009 | C602: D2508221231023320401 | D602: Additional Package | E602: MA001604 | F602: Quadcell | G602: Active | H602: 08/22/2025 12:31:02 | I602: 500M / 128Kbps / Natural Day
A603: CMLink-00 | B603: 116008 | D603: Additional Package | E603: TestRelease | F603: Quadcell | G603: Draft | H603: 08/22/2025 11:45:33 | I603: 1024M / 1Mbps / 24 Hours,2048M / 0Kbps / 24 Hours
A604: CMLink-00 | B604: 114270 | C604: D2508211444020040959 | D604: Additional Package | E604: MA001603 | F604: Quadcell | G604: Active | H604: 08/21/2025 14:44:02 | I604: 30720M / 0Kbps / Natural Day
A605: CMLink-00 | B605: 114269 | C605: D2508211443202192418 | D605: Additional Package | E605: MA001603 | F605: Quadcell | G605: Active | H605: 08/21/2025 14:43:20 | I605: 30720M / 0Kbps / Natural Day
A606: CMLink-00 | B606: 113824 | C606: D2508201101025661348 | D606: Additional Package | E606: MA001602 | F606: Quadcell | G606: Active | H606: 08/20/2025 11:01:02 | I606: 8G / 256Kbps / Natural Day
A607: CMLink-00 | B607: 113823 | C607: D2508201100161148779 | D607: Additional Package | E607: MA001601 | F607: Quadcell | G607: Active | H607: 08/20/2025 11:00:16 | I607: 6G / 256Kbps / Natural Day
A608: CMLink-00 | B608: 113822 | C608: D2508201100155737532 | D608: Additional Package | E608: MA001600 | F608: Quadcell | G608: Active | H608: 08/20/2025 11:00:15 | I608: 4G / 256Kbps / Natural Day
A609: CMLink-00 | B609: 113820 | C609: D2508201100142151787 | D609: Additional Package | E609: MA001598 | F609: Quadcell | G609: Active | H609: 08/20/2025 11:00:14 | I609: 6G / 256Kbps / Natural Day
A610: CMLink-00 | B610: 113821 | C610: D2508201100147766939 | D610: Additional Package | E610: MA001599 | F610: Quadcell | G610: Active | H610: 08/20/2025 11:00:14 | I610: 8G / 256Kbps / Natural Day
A611: CMLink-00 | B611: 113818 | C611: D2508201100129529100 | D611: Additional Package | E611: MA001596 | F611: Quadcell | G611: Active | H611: 08/20/2025 11:00:13 | I611: 4G / 256Kbps / Natural Day
A612: CMLink-00 | B612: 113819 | C612: D2508201100135286252 | D612: Additional Package | E612: MA001597 | F612: Quadcell | G612: Active | H612: 08/20/2025 11:00:13 | I612: 6G / 256Kbps / Natural Day
A613: CMLink-00 | B613: 113817 | C613: D2508201100124015450 | D613: Additional Package | E613: MA001595 | F613: Quadcell | G613: Active | H613: 08/20/2025 11:00:12 | I613: 8G / 256Kbps / Natural Day
A614: CMLink-00 | B614: 113815 | C614: D2508201100112700081 | D614: Additional Package | E614: MA001593 | F614: Quadcell | G614: Active | H614: 08/20/2025 11:00:11 | I614: 4G / 256Kbps / Natural Day
A615: CMLink-00 | B615: 113816 | C615: D2508201100118222491 | D615: Additional Package | E615: MA001594 | F615: Quadcell | G615: Active | H615: 08/20/2025 11:00:11 | I615: 6G / 256Kbps / Natural Day
...

Sheet Config
B1: API Command | C1: Parameter | H1: Quota
B2: heartbeat | H2: 100MB
B3: qrysub | C3: imsi | H3: 200MB
B4: qrypacklist | C4: imsi | E4: subscriptionId | H4: 300MB
B5: queryQosQuota | C5: imsi | E5: subscriptionId | H5: 400MB
B6: addpack | C6: imsi | D6: packCode | H6: 500MB
B7: delpack | C7: imsi | D7: packCode | E7: subscriptionId | F7: packOrderSn | H7: 512MB
B8: suspend | C8: imsi | H8: 600MB
B9: recover | C9: imsi | H9: 700MB
B10: quota/topup | C10: imsi | D10: quota | E10: subscriptionId | H10: 800MB
H11: 900MB
H12: 1000MB
H13: 1024MB
H14: 1536MB
H15: 2048MB
H16: 2560MB
H17: 3072MB
H18: 3584MB
H19: 4096MB
H20: 4608MB
H21: 5120MB
H22: 5632MB
... H35: 51200MB
